<?xml version="1.0" encoding="utf-8"?>
<!-- This URDF was automatically created by SolidWorks to URDF Exporter! Originally created by Stephen Brawner (brawner@gmail.com) 
     Commit Version: 1.6.0-4-g7f85cfe  Build Version: 1.6.7995.38578
     For more information, please see http://wiki.ros.org/sw_urdf_exporter -->
<robot
  name="robot_arm">
  <link
    name="base_link">
    <inertial>
      <origin
        xyz="-0.010426 -0.0048537 0.043274"
        rpy="0 0 0" />
      <mass
        value="0.072556" />
      <inertia
        ixx="1.8443E-05"
        ixy="6.7354E-12"
        ixz="-2.396E-08"
        iyy="4.189E-05"
        iyz="6.4075E-08"
        izz="3.9774E-05" />
    </inertial>
    <visual>
      <origin
        xyz="0 0 0"
        rpy="0 0 0" />
      <geometry>
        <mesh
          filename="package://robot_arm/meshes/base_link.STL" />
      </geometry>
      <material
        name="">
        <color
          rgba="0.79216 0.81961 0.93333 1" />
      </material>
    </visual>
    <collision>
      <origin
        xyz="0 0 0"
        rpy="0 0 0" />
      <geometry>
        <mesh
          filename="package://robot_arm/meshes/base_link.STL" />
      </geometry>
    </collision>
  </link>
  <link
    name="link1">
    <inertial>
      <origin
        xyz="0.042062 -0.0059288 -0.025684"
        rpy="0 0 0" />
      <mass
        value="0.20718" />
      <inertia
        ixx="0.00037471"
        ixy="2.0599E-05"
        ixz="-4.7344E-06"
        iyy="0.0010314"
        iyz="1.2339E-05"
        izz="0.0007805" />
    </inertial>
    <visual>
      <origin
        xyz="0 0 0"
        rpy="0 0 0" />
      <geometry>
        <mesh
          filename="package://robot_arm/meshes/link1.STL" />
      </geometry>
      <material
        name="">
        <color
          rgba="0.79216 0.81961 0.93333 1" />
      </material>
    </visual>
    <collision>
      <origin
        xyz="0 0 0"
        rpy="0 0 0" />
      <geometry>
        <mesh
          filename="package://robot_arm/meshes/link1.STL" />
      </geometry>
    </collision>
  </link>
  <joint
    name="joint1"
    type="revolute">
    <origin
      xyz="0 0 0.09255"
      rpy="0 0 0" />
    <parent
      link="base_link" />
    <child
      link="link1" />
    <axis
      xyz="0 0 1" />
    <limit
      lower="0"
      upper="3.1416"
      effort="0"
      velocity="0" />
  </joint>
  <link
    name="link2">
    <inertial>
      <origin
        xyz="0.0515 -2.1441E-15 -0.0265"
        rpy="0 0 0" />
      <mass
        value="0.015058" />
      <inertia
        ixx="8.0384E-06"
        ixy="-1.9457E-20"
        ixz="7.779E-21"
        iyy="1.2213E-05"
        iyz="3.2781E-21"
        izz="5.6572E-06" />
    </inertial>
    <visual>
      <origin
        xyz="0 0 0"
        rpy="0 0 0" />
      <geometry>
        <mesh
          filename="package://robot_arm/meshes/link2.STL" />
      </geometry>
      <material
        name="">
        <color
          rgba="0.79216 0.81961 0.93333 1" />
      </material>
    </visual>
    <collision>
      <origin
        xyz="0 0 0"
        rpy="0 0 0" />
      <geometry>
        <mesh
          filename="package://robot_arm/meshes/link2.STL" />
      </geometry>
    </collision>
  </link>
  <joint
    name="joint2"
    type="revolute">
    <origin
      xyz="0.0108 -0.03605 0.019"
      rpy="1.5708 0 0" />
    <parent
      link="link1" />
    <child
      link="link2" />
    <axis
      xyz="0 0 1" />
    <limit
      lower="0"
      upper="3.1416"
      effort="0"
      velocity="0" />
  </joint>
  <link
    name="link3">
    <inertial>
      <origin
        xyz="0.022728 -0.00067956 0.02531"
        rpy="0 0 0" />
      <mass
        value="0.041173" />
      <inertia
        ixx="8.8942E-06"
        ixy="-9.848E-08"
        ixz="-2.396E-08"
        iyy="1.4512E-05"
        iyz="-6.4075E-08"
        izz="8.7539E-06" />
    </inertial>
    <visual>
      <origin
        xyz="0 0 0"
        rpy="0 0 0" />
      <geometry>
        <mesh
          filename="package://robot_arm/meshes/link3.STL" />
      </geometry>
      <material
        name="">
        <color
          rgba="0.79216 0.81961 0.93333 1" />
      </material>
    </visual>
    <collision>
      <origin
        xyz="0 0 0"
        rpy="0 0 0" />
      <geometry>
        <mesh
          filename="package://robot_arm/meshes/link3.STL" />
      </geometry>
    </collision>
  </link>
  <joint
    name="joint3"
    type="revolute">
    <origin
      xyz="0.103 0 -0.053"
      rpy="0 0 -1.5708" />
    <parent
      link="link2" />
    <child
      link="link3" />
    <axis
      xyz="0 0 1" />
    <limit
      lower="0"
      upper="3.1416"
      effort="0"
      velocity="0" />
  </joint>
  <link
    name="link4">
    <inertial>
      <origin
        xyz="-0.00068355 0.0097889 -0.026302"
        rpy="0 0 0" />
      <mass
        value="0.031668" />
      <inertia
        ixx="8.0607E-06"
        ixy="-6.7354E-12"
        ixz="6.4075E-08"
        iyy="4.6431E-06"
        iyz="2.396E-08"
        izz="5.554E-06" />
    </inertial>
    <visual>
      <origin
        xyz="0 0 0"
        rpy="0 0 0" />
      <geometry>
        <mesh
          filename="package://robot_arm/meshes/link4.STL" />
      </geometry>
      <material
        name="">
        <color
          rgba="0.75294 0.75294 0.75294 1" />
      </material>
    </visual>
    <collision>
      <origin
        xyz="0 0 0"
        rpy="0 0 0" />
      <geometry>
        <mesh
          filename="package://robot_arm/meshes/link4.STL" />
      </geometry>
    </collision>
  </link>
  <joint
    name="joint4"
    type="revolute">
    <origin
      xyz="0.0978 0.0015 -0.00095"
      rpy="3.1416 0 -1.5708" />
    <parent
      link="link3" />
    <child
      link="link4" />
    <axis
      xyz="0 0 1" />
    <limit
      lower="0"
      upper="3.1416"
      effort="0"
      velocity="0" />
  </joint>
  <link
    name="left_finger">
    <inertial>
      <origin
        xyz="0.004363 0.0042293 -0.01575"
        rpy="0 0 0" />
      <mass
        value="0.018457" />
      <inertia
        ixx="4.1532E-06"
        ixy="1.1861E-07"
        ixz="-2.4731E-10"
        iyy="7.4076E-06"
        iyz="-1.4694E-10"
        izz="4.6333E-06" />
    </inertial>
    <visual>
      <origin
        xyz="0 0 0"
        rpy="0 0 0" />
      <geometry>
        <mesh
          filename="package://robot_arm/meshes/left_finger.STL" />
      </geometry>
      <material
        name="">
        <color
          rgba="0.79216 0.81961 0.93333 1" />
      </material>
    </visual>
    <collision>
      <origin
        xyz="0 0 0"
        rpy="0 0 0" />
      <geometry>
        <mesh
          filename="package://robot_arm/meshes/left_finger.STL" />
      </geometry>
    </collision>
  </link>
  <joint
    name="grip_joint1"
    type="prismatic">
    <origin
      xyz="-0.06744 0.036228 0.0065437"
      rpy="1.5708 0 3.1416" />
    <parent
      link="link4" />
    <child
      link="left_finger" />
    <axis
      xyz="0 -1 0" />
    <limit
      lower="0"
      upper="0"
      effort="0"
      velocity="0" />
  </joint>
  <link
    name="right_finger">
    <inertial>
      <origin
        xyz="0.004363 -0.0042293 -0.01575"
        rpy="0 0 0" />
      <mass
        value="0.018457" />
      <inertia
        ixx="4.1532E-06"
        ixy="-1.1861E-07"
        ixz="2.4731E-10"
        iyy="7.4076E-06"
        iyz="-1.4694E-10"
        izz="4.6333E-06" />
    </inertial>
    <visual>
      <origin
        xyz="0 0 0"
        rpy="0 0 0" />
      <geometry>
        <mesh
          filename="package://robot_arm/meshes/right_finger.STL" />
      </geometry>
      <material
        name="">
        <color
          rgba="0.79216 0.81961 0.93333 1" />
      </material>
    </visual>
    <collision>
      <origin
        xyz="0 0 0"
        rpy="0 0 0" />
      <geometry>
        <mesh
          filename="package://robot_arm/meshes/right_finger.STL" />
      </geometry>
    </collision>
  </link>
  <joint
    name="grip_joint2"
    type="prismatic">
    <origin
      xyz="-0.06744 0.036138 -0.065096"
      rpy="1.5708 0 3.1416" />
    <parent
      link="link4" />
    <child
      link="right_finger" />
    <axis
      xyz="0 -1 0" />
    <limit
      lower="0"
      upper="0"
      effort="0"
      velocity="0" />
  </joint>
  <link
    name="end_effector">
    <inertial>
      <origin
        xyz="-0.016482 -1.618E-06 -0.0064867"
        rpy="0 0 0" />
      <mass
        value="0.057795" />
      <inertia
        ixx="3.0553E-05"
        ixy="2.5795E-13"
        ixz="-4.6718E-07"
        iyy="1.402E-05"
        iyz="-2.5404E-08"
        izz="2.4228E-05" />
    </inertial>
    <visual>
      <origin
        xyz="0 0 0"
        rpy="0 0 0" />
      <geometry>
        <mesh
          filename="package://robot_arm/meshes/end_effector.STL" />
      </geometry>
      <material
        name="">
        <color
          rgba="0.79216 0.81961 0.93333 1" />
      </material>
    </visual>
    <collision>
      <origin
        xyz="0 0 0"
        rpy="0 0 0" />
      <geometry>
        <mesh
          filename="package://robot_arm/meshes/end_effector.STL" />
      </geometry>
    </collision>
  </link>
  <joint
    name="end-joint"
    type="fixed">
    <origin
      xyz="-0.05286 0.019218 -0.029276"
      rpy="1.5708 0 -3.1416" />
    <parent
      link="link4" />
    <child
      link="end_effector" />
    <axis
      xyz="0 0 0" />
  </joint>
</robot>