<?xml version="1.0" encoding="utf-8"?>
<!-- This URDF was automatically created by SolidWorks to URDF Exporter! Originally created by Stephen Brawner (brawner@gmail.com) 
     Commit Version: 1.6.0-4-g7f85cfe  Build Version: 1.6.7995.38578
     For more information, please see http://wiki.ros.org/sw_urdf_exporter -->
<robot
  name="Robot_Arm">
  <link
    name="base_link">
    <inertial>
      <origin
        xyz="-0.0104259249124962 -0.0048536572277758 0.0432744746088849"
        rpy="0 0 0" />
      <mass
        value="0.0725564097125622" />
      <inertia
        ixx="1.84434778729453E-05"
        ixy="6.73538682758001E-12"
        ixz="-2.3959547324024E-08"
        iyy="4.18895782173143E-05"
        iyz="6.4075366139781E-08"
        izz="3.97742050247117E-05" />
    </inertial>
    <visual>
      <origin
        xyz="0 0 0"
        rpy="0 0 0" />
      <geometry>
        <mesh
          filename="package://Robot_Arm/meshes/base_link.STL" />
      </geometry>
      <material
        name="">
        <color
          rgba="0.792156862745098 0.819607843137255 0.933333333333333 1" />
      </material>
    </visual>
    <collision>
      <origin
        xyz="0 0 0"
        rpy="0 0 0" />
      <geometry>
        <mesh
          filename="package://Robot_Arm/meshes/base_link.STL" />
      </geometry>
    </collision>
  </link>
  <link
    name="Link1">
    <inertial>
      <origin
        xyz="0.0420622615308821 -0.00592880515232835 -0.0256843612112551"
        rpy="0 0 0" />
      <mass
        value="0.207180993005197" />
      <inertia
        ixx="0.000374708377115792"
        ixy="2.05992772371561E-05"
        ixz="-4.73438905207625E-06"
        iyy="0.00103137138329276"
        iyz="1.23389452660578E-05"
        izz="0.000780498008648986" />
    </inertial>
    <visual>
      <origin
        xyz="0 0 0"
        rpy="0 0 0" />
      <geometry>
        <mesh
          filename="package://Robot_Arm/meshes/Link1.STL" />
      </geometry>
      <material
        name="">
        <color
          rgba="0.792156862745098 0.819607843137255 0.933333333333333 1" />
      </material>
    </visual>
    <collision>
      <origin
        xyz="0 0 0"
        rpy="0 0 0" />
      <geometry>
        <mesh
          filename="package://Robot_Arm/meshes/Link1.STL" />
      </geometry>
    </collision>
  </link>
  <joint
    name="Joint1"
    type="revolute">
    <origin
      xyz="0 0 0.09255"
      rpy="0 0 0" />
    <parent
      link="base_link" />
    <child
      link="Link1" />
    <axis
      xyz="0 0 1" />
    <limit
      lower="0"
      upper="3.1416"
      effort="0"
      velocity="0" />
  </joint>
  <link
    name="Link2">
    <inertial>
      <origin
        xyz="0.0514999999999985 -1.70002900645727E-15 -0.0265000000000009"
        rpy="0 0 0" />
      <mass
        value="0.0150579864214192" />
      <inertia
        ixx="8.03838158687281E-06"
        ixy="-1.73378605295587E-20"
        ixz="7.37479334416483E-23"
        iyy="1.22131883719689E-05"
        iyz="-4.29407072392088E-22"
        izz="5.65715727925143E-06" />
    </inertial>
    <visual>
      <origin
        xyz="0 0 0"
        rpy="0 0 0" />
      <geometry>
        <mesh
          filename="package://Robot_Arm/meshes/Link2.STL" />
      </geometry>
      <material
        name="">
        <color
          rgba="0.792156862745098 0.819607843137255 0.933333333333333 1" />
      </material>
    </visual>
    <collision>
      <origin
        xyz="0 0 0"
        rpy="0 0 0" />
      <geometry>
        <mesh
          filename="package://Robot_Arm/meshes/Link2.STL" />
      </geometry>
    </collision>
  </link>
  <joint
    name="Joint2"
    type="revolute">
    <origin
      xyz="0.0108 -0.03605 0.019"
      rpy="1.5708 0 0" />
    <parent
      link="Link1" />
    <child
      link="Link2" />
    <axis
      xyz="0 0 1" />
    <limit
      lower="0"
      upper="3.1416"
      effort="0"
      velocity="0" />
  </joint>
  <link
    name="Link3">
    <inertial>
      <origin
        xyz="0.022728048874843 -0.000679561249228244 0.0253101496525927"
        rpy="0 0 0" />
      <mass
        value="0.0411732267600477" />
      <inertia
        ixx="8.89417969716542E-06"
        ixy="-9.8479551916094E-08"
        ixz="-2.39595473238911E-08"
        iyy="1.45118250069406E-05"
        iyz="-6.40753661397687E-08"
        izz="8.75387222329412E-06" />
    </inertial>
    <visual>
      <origin
        xyz="0 0 0"
        rpy="0 0 0" />
      <geometry>
        <mesh
          filename="package://Robot_Arm/meshes/Link3.STL" />
      </geometry>
      <material
        name="">
        <color
          rgba="0.792156862745098 0.819607843137255 0.933333333333333 1" />
      </material>
    </visual>
    <collision>
      <origin
        xyz="0 0 0"
        rpy="0 0 0" />
      <geometry>
        <mesh
          filename="package://Robot_Arm/meshes/Link3.STL" />
      </geometry>
    </collision>
  </link>
  <joint
    name="Joint3"
    type="revolute">
    <origin
      xyz="0.103 0 -0.053"
      rpy="0 0 -1.5708" />
    <parent
      link="Link2" />
    <child
      link="Link3" />
    <axis
      xyz="0 0 1" />
    <limit
      lower="0"
      upper="3.1416"
      effort="0"
      velocity="0" />
  </joint>
  <link
    name="Link4">
    <inertial>
      <origin
        xyz="-0.000683553147996951 0.00978890206482536 -0.0263024391761712"
        rpy="0 0 0" />
      <mass
        value="0.0316676572660873" />
      <inertia
        ixx="8.06071840594677E-06"
        ixy="-6.73538676296777E-12"
        ixz="6.40753661397883E-08"
        iyy="4.64305606634161E-06"
        iyz="2.39595473238741E-08"
        izz="5.55403753556937E-06" />
    </inertial>
    <visual>
      <origin
        xyz="0 0 0"
        rpy="0 0 0" />
      <geometry>
        <mesh
          filename="package://Robot_Arm/meshes/Link4.STL" />
      </geometry>
      <material
        name="">
        <color
          rgba="0.752941176470588 0.752941176470588 0.752941176470588 1" />
      </material>
    </visual>
    <collision>
      <origin
        xyz="0 0 0"
        rpy="0 0 0" />
      <geometry>
        <mesh
          filename="package://Robot_Arm/meshes/Link4.STL" />
      </geometry>
    </collision>
  </link>
  <joint
    name="Joint4"
    type="revolute">
    <origin
      xyz="0.0978 0.0015 -0.00095"
      rpy="3.1416 0 -1.5708" />
    <parent
      link="Link3" />
    <child
      link="Link4" />
    <axis
      xyz="0 0 1" />
    <limit
      lower="0"
      upper="3.1416"
      effort="0"
      velocity="0" />
  </joint>
  <link
    name="GripL">
    <inertial>
      <origin
        xyz="0.00436302017417017 0.00422927185214711 -0.0157504632594223"
        rpy="0 0 0" />
      <mass
        value="0.0184570467495853" />
      <inertia
        ixx="4.15319001962167E-06"
        ixy="1.18608250402742E-07"
        ixz="-2.47307712977721E-10"
        iyy="7.40764663567909E-06"
        iyz="-1.46937845773757E-10"
        izz="4.63330776046162E-06" />
    </inertial>
    <visual>
      <origin
        xyz="0 0 0"
        rpy="0 0 0" />
      <geometry>
        <mesh
          filename="package://Robot_Arm/meshes/GripL.STL" />
      </geometry>
      <material
        name="">
        <color
          rgba="0.792156862745098 0.819607843137255 0.933333333333333 1" />
      </material>
    </visual>
    <collision>
      <origin
        xyz="0 0 0"
        rpy="0 0 0" />
      <geometry>
        <mesh
          filename="package://Robot_Arm/meshes/GripL.STL" />
      </geometry>
    </collision>
  </link>
  <joint
    name="Grip_Joint1"
    type="prismatic">
    <origin
      xyz="-0.06744 0.036228 0.0065437"
      rpy="1.5708 0 3.1416" />
    <parent
      link="Link4" />
    <child
      link="GripL" />
    <axis
      xyz="0 1 0" />
    <limit
      lower="0"
      upper="0"
      effort="0"
      velocity="0" />
  </joint>
  <link
    name="GripR">
    <inertial>
      <origin
        xyz="0.00436302017417026 -0.00422927185215562 -0.0157495367405776"
        rpy="0 0 0" />
      <mass
        value="0.0184570467495853" />
      <inertia
        ixx="4.15319001962167E-06"
        ixy="-1.18608250402786E-07"
        ixz="2.47307712971134E-10"
        iyy="7.40764663567908E-06"
        iyz="-1.46937845773272E-10"
        izz="4.6333077604616E-06" />
    </inertial>
    <visual>
      <origin
        xyz="0 0 0"
        rpy="0 0 0" />
      <geometry>
        <mesh
          filename="package://Robot_Arm/meshes/GripR.STL" />
      </geometry>
      <material
        name="">
        <color
          rgba="0.792156862745098 0.819607843137255 0.933333333333333 1" />
      </material>
    </visual>
    <collision>
      <origin
        xyz="0 0 0"
        rpy="0 0 0" />
      <geometry>
        <mesh
          filename="package://Robot_Arm/meshes/GripR.STL" />
      </geometry>
    </collision>
  </link>
  <joint
    name="Grip_Joint2"
    type="prismatic">
    <origin
      xyz="-0.06744 0.036138 -0.065096"
      rpy="1.5708 0 -3.1416" />
    <parent
      link="Link4" />
    <child
      link="GripR" />
    <axis
      xyz="0 1 0" />
    <limit
      lower="0"
      upper="0"
      effort="0"
      velocity="0" />
  </joint>
  <link
    name="End-Effector">
    <inertial>
      <origin
        xyz="-0.0164822426429336 -1.61803310824715E-06 -0.00648665413103859"
        rpy="0 0 0" />
      <mass
        value="0.0577947757867498" />
      <inertia
        ixx="3.05532861900538E-05"
        ixy="2.57952437843824E-13"
        ixz="-4.671829172981E-07"
        iyy="1.4019553678633E-05"
        iyz="-2.54038789153586E-08"
        izz="2.4228055409743E-05" />
    </inertial>
    <visual>
      <origin
        xyz="0 0 0"
        rpy="0 0 0" />
      <geometry>
        <mesh
          filename="package://Robot_Arm/meshes/End-Effector.STL" />
      </geometry>
      <material
        name="">
        <color
          rgba="0.792156862745098 0.819607843137255 0.933333333333333 1" />
      </material>
    </visual>
    <collision>
      <origin
        xyz="0 0 0"
        rpy="0 0 0" />
      <geometry>
        <mesh
          filename="package://Robot_Arm/meshes/End-Effector.STL" />
      </geometry>
    </collision>
  </link>
  <joint
    name="End-Joint"
    type="fixed">
    <origin
      xyz="-0.05286 0.019218 -0.029276"
      rpy="1.5708 0 -3.1416" />
    <parent
      link="Link4" />
    <child
      link="End-Effector" />
    <axis
      xyz="0 0 0" />
  </joint>
</robot>